Workbook
Name August: #REF!
Name July: #REF!
Name May: #REF!
Name November: #REF!
Name October: #REF!
Name September: #REF!

Sheet Stmt of Changes in Ass
A1: Republic of the Philippines
A2: Province of Leyte
A3: Municipality of Jaro
A5: Statement of Changes in Net Assets/Equity
A7: For the Year Ended December 31, 2020
H9: Accumulated
H10: Surpluses/(Deficits)
H12: 2019 | J12: 2021
A14: Beginning Balance as of January 01,2020 | J14: 3.2815843e+08 | K14: Gov. Equity
A15: Add (Deduct)
B16: Change in Accounting Policy
B17: Prior Period Errors | J17: -13239701 | K17: Prior Period
A18: Restated Balance | J18: =J14+J17 -> 3.1491873e+08
A19: Add (Deduct) Changes in Net Assets/Equity dering the year
A20: Adjustment of net revenue recognized directly in net assets/equity | J20: 16977113
A21: Surplus (Deficit) for the period | J21: 51461424 | K21: Income
A22: Total recognized revenue and expenses for the period | J22: =SUM(J20:J21) -> 68438537
A24: Balance at March 31,2022. | J24: =J18+J22 -> 3.8335727e+08 | K24: checking balances
A28: Prepared by: | F28: Certified Correct:
A31: JJUVELYN A. CABARRUBIAS | F31: JUDY G. PARADO, CPA
A32: Job Order Employee | F32: Municipal Accountant

Sheet Schedule FP
A1: Republic of the Philippines
A2: Province of Leyte
A3: Municipality of Jaro
A5: SCHEDULE FOR INCOME AND EXPENSES
A6: For the Quarter Ended March 2022
A7: GENERAL FUND
A9: Account Code | E9: ACCOUNT TITLE | F9: AMOUNT
A11: 4 | B11: I N C O M E
A12: 4 | B12: 01 | C12: TAX REVENUE
A13: 4 | B13: 01 | C13: 01 | D13: Tax Revenue - Individual and Corporation
A14: 4 | B14: 01 | C14: 01 | D14: 020 | E14: Professional Tax | F14: =#REF! -> #REF!
A15: 4 | B15: 01 | C15: 01 | D15: 050 | E15: Community Tax | F15: =#REF! -> #REF!
A16: 4 | B16: 01 | C16: 02 | D16: Tax Revenue - Property
A17: 4 | B17: 01 | C17: 02 | D17: 040 | E17: Real Property Tax- Basic | F17: =#REF! -> #REF!
A18: 4 | B18: 01 | C18: 02 | D18: 041 | E18: Discount on Real Property Tax- Basic | F18: =SUM(-#REF!) -> #REF!
A19: 4 | B19: 01 | C19: 02 | D19: 050 | E19: Special Education Tax | F19: 0
A20: 4 | B20: 01 | C20: 02 | D20: 051 | E20: Discount on Special Education Tax | F20: 0
A21: 4 | B21: 01 | C21: 02 | D21: 060 | E21: Special Levy on Idle Lands | F21: 0
A22: 4 | B22: 01 | C22: 02 | D22: 070 | E22: Special Levy on Lands Benefited by Public Works Projects | F22: 0
A23: 4 | B23: 01 | C23: 02 | D23: 080 | E23: Real Property Transfer Tax | F23: =#REF! -> #REF!
A24: 4 | B24: 01 | C24: 03 | D24: Tax Revenue - Goods and Services
A25: 4 | B25: 01 | C25: 03 | D25: 030 | E25: Business Tax | F25: =#REF! -> #REF!
A26: 4 | B26: 01 | C26: 03 | D26: 040 | E26: Tax on Sand, Gravel and Other Quarry Products | F26: =#REF! -> #REF!
A27: 4 | B27: 01 | C27: 03 | D27: 050 | E27: Tax on Delivery Trucks and Vans | F27: =#REF! -> #REF!
A28: 4 | B28: 01 | C28: 03 | D28: 060 | E28: Amusement Tax | F28: =#REF! -> #REF!
A29: 4 | B29: 01 | C29: 03 | D29: 070 | E29: Franchise Tax | F29: =#REF! -> #REF!
A30: 4 | B30: 01 | C30: 03 | D30: 080 | E30: Printing and Publication Tax | F30: 0
A31: 4 | B31: 01 | C31: 04 | D31: Tax Revenue - Others
A32: 4 | B32: 01 | C32: 04 | D32: 990 | E32: Other Taxes | F32: 0
A33: 4 | B33: 01 | C33: 05 | D33: Tax Revenue - Fines and Penalties
A34: 4 | B34: 01 | C34: 05 | D34: 010 | E34: Tax Revenue - Fines and Penalties - Taxes on Individual and Corporation | F34: 0
A35: 4 | B35: 01 | C35: 05 | D35: 020 | E35: Tax Revenue - Fines and Penalties - Property Taxes
A36: 4 | B36: 01 | C36: 05 | D36: 030 | E36: Tax Revenue - Fines and Penalties - Taxes on Goods and Services
A37: 4 | B37: 01 | C37: 05 | D37: 040 | E37: Tax Revenue - Fines and Penalties - Other Taxes
A38: TOTAL
A39: 4 | B39: 01 | C39: 06 | D39: Share from National Taxes
A40: 4 | B40: 01 | C40: 06 | D40: 010 | E40: Share from Internal Revenue Collections (IRA) | H40: =SUM(#REF!) -> #REF!
A41: 4 | B41: 01 | C41: 06 | D41: 020 | E41: Share from Expanded Value Added Tax | H41: =SUM(F38,F45,F90,F110)-F18 -> #REF! | I41: =H40-H41 -> #REF!
A42: 4 | B42: 01 | C42: 06 | D42: 030 | E42: Share from National Wealth
A43: 4 | B43: 01 | C43: 06 | D43: 040 | E43: Share from Tobacco Excise Tax (RA 7171 and 8240)
...

Sheet Stmt. of Fin'l. Performance
A1: Republic of the Philippines
A2: Province of Leyte
A3: MUNICIPALITY OF JARO
A5: STATEMENT OF FINANCIAL PERFORMANCE
A6: GENERAL FUND
A7: For the year ended December 31, 2020
A9: PARTICULARS | D9: 2019 | F9: 2021
A10: REVENUE
B11: Tax Revenue | D11: ='Schedule FP'!F38 -> 0 | F11: 4812161.3
B12: Share from Internal Revenue Collections | D12: =SUM('Schedule FP'!F45) -> 0 | F12: 166003264
B13: Other Share from National Taxes
B14: Service and Business Income | D14: =SUM('Schedule FP'!F90) -> 0 | F14: 10759217
B15: Shares, Grants and Donations | D15: =SUM('Schedule FP'!F110) -> 0 | F15: 415709.59
B16: Gains | D16: ='Schedule FP'!F132 -> 0 | F16: ='[1]Schedule FP'!H132 -> #REF!
B17: Other Income | D17: ='Schedule FP'!F132 -> 0 | F17: ='[1]Schedule FP'!H132 -> #REF!
A18: TOTAL REVENUE | D18: =SUM(D11:D17) -> 0 | F18: =SUM(F11:F17) -> #REF!
A19: Less: Current Operating Expenses
B20: Personnel Services | D20: ='Schedule FP'!F166 -> 0 | F20: 88363078
B21: Maintenance and Other Operating Expenses | D21: ='Schedule FP'!F257 -> 0 | F21: 38129411
B22: Financial Expenses | D22: =SUM('Schedule FP'!F266) -> 0 | F22: 21234.82
B23: Non-Cash Expenses | D23: ='Schedule FP'!F312 -> 0 | F23: 2972161.8
A24: CURRENT OPERATING EXPENSES | D24: =SUM(D20:D23) -> 0 | F24: =SUM(F20:F23) -> 1.2948589e+08
A25: Surplus (Deficit) from Current Operation | D25: =D18-D24 -> 0 | F25: =F18-F24 -> #REF!
B26: Add (Deduct):
C27: Transfers, Assistance and Subsidy from | D27: 0 | F27: 0
C28: Transfers, Assistance and Subsidy to LGUs | D28: =-'Schedule FP'!F235 -> 0 | F28: -1043041.9
A29: SURPLUS (DEFICIT) FOR THE PERIOD | D29: =D25+D28 -> 0 | F29: =F25+F28 -> #REF!
A31: Prepared by: | C31: Certified Correct:
B33: JUVELYN A. CABARRUBIAS | D33: JUDY G. PARADO, CPA
B34: Job Order Employee | D34: Municipal Accountant

Sheet Income Statement
A1: Republic of the Philippines
A2: Province of Leyte
A3: Municipality of Jaro
A5: STATEMENT OF INCOME AND EXPENSES
G6: General Fund
A7: For the Year Ended December 31, 2015
A8: (With Comparative Figures for CY 2014)
H11: 2015 | J11: 2014
A13: TAX REVENUE
B14: Local Taxes
C15: Amusement Tax | H15: =#REF! -> #REF! | J15: 3762.5
C16: Business Tax | H16: =#REF! -> #REF! | J16: 989643.8
C17: Community Tax | H17: =#REF! -> #REF! | J17: 615670.15
C18: Franchise Tax | H18: ='Schedule FP'!D17 -> 040 | J18: 1530
C19: Occupation Tax | H19: =#REF! -> #REF! | J19: 92820
C20: Printing and Publication Tax
C21: Property Transfer Tax
C22: Real Property Tax | H22: =#REF! -> #REF! | J22: 322494.86
D23: Less: Discount on Real Property Tax | H23: =-#REF! -> #REF! | J23: -42238.94
C24: Real Property Tax on Idle Lands
C25: Special Assessment Tax
C26: Special Education Tax
D27: Less: Discount on Special Education Tax
C28: Tax on Delivery Trucks and Vans | H28: =#REF! -> #REF! | J28: 30150
C29: Tax on Sand, Gravel and other Quarry Products | H29: =#REF! -> #REF! | J29: 70000
C30: Other Local Taxes | H30: =#REF! -> #REF! | J30: 8130
C31: Fines and Penalties-Local Taxes | H31: =#REF! -> #REF! | J31: 199482.86
C32: Total Local Taxes | H32: =SUM(H15:H31) -> #REF! | J32: =SUM(J15:J31) -> 2291445.2
A33: GENERAL INCOME ACCOUNTS
B34: Internal Revenue Allotment | H34: =#REF! -> #REF! | J34: 81867039
B35: Permits and Licenses
C36: Fees on Weights and Measures | H36: =#REF! -> #REF! | J36: 8870
C37: Fishery Rental Fees
C38: Franchising and Licensing Fees
C39: Motor Vehicles Users Charge
C40: Permit Fees | H40: =#REF! -> #REF! | J40: 463848.61
C41: Registration Fees | H41: =#REF! -> #REF! | J41: 68460
C42: Other Permits and Licenses | H42: =#REF! -> #REF! | J42: 132884.5
C43: Fines and Penalties - Permits and Licenses
C44: Total Permits and Licenses | H44: =SUM(H36:H43) -> #REF! | J44: =SUM(J36:J43) -> 674063.11
...

Sheet Schedule Balance Sheet
A1: Republic of the Philippines
A2: Province of Leyte
A3: Municipality of Jaro
A5: SCHEDULE OF BALANCE SHEET
A6: As of December 31, 2015
A7: General Fund
B10: Account | D10: Amount
B11: Code
A12: Cash
A13: Cash in Vault | B13: 101 | E13: 3359712.5
A15: Petty Cash Fund (GF) | B15: 104-1 | E15: 23642.37
A16: Petty Cash Fund (AICS) | B16: 104-2 | E16: 20000
E17: =E15+E16 -> 43642.37
A19: Payroll Fund | B19: 106 | E19: =#REF! -> #REF!
A21: Cash in Bank-(LBP) IRA | B21: 111-1A | E21: 11642128
A22: Cash in Bank-(PNB)LARP Account | B22: 111-1B | E22: 14328.66
A23: Cash in Bank-(PNB)LGU Equity Account | B23: 111-1C | E23: 33326.04
A24: Cash in Bank-(PNB) 20% Development Fund Account | B24: 111-2 | E24: -15.49
A25: Cash in Bank-(PPSB) 5% Calamity Fund Account | B25: 111-3 | E25: 9081383
A26: Cash in Bank-(LBP) Performance Challenge Fund | B26: 111-7 | E26: 3799238.4
A27: Cash in Bank-(LBP) SALINTUBIG | B27: 111-8 | E27: 12452467
A28: Cash in Bank-(LBP) Flood Control | B28: 111-9 | E28: 8679983.7
A29: Cash in Bank-(LBP) Sports Complex | B29: 111-10 | E29: 1025000
A30: Cash in Bank-(LBP) RAY Project | B30: 111-11 | E30: 1272462.7
A31: Cash in Bank-(LBP) GPBP | B31: 111-12 | E31: 3010000
A32: Cash in Bank-(LBP) BRGY.FACILITIES (RAY) | B32: 111-13 | E32: 20153517
A33: Total | E33: =SUM(E21:E32) -> 71163818
A35: Total Cash | E35: =E13+E17+E33+E19 -> #REF!
A37: Receivables
A38: Real Property Tax Receivables | B38: 127 | E38: 24158078
A39: Due from NGAs | B39: 136 | E39: =#REF! -> #REF!
A40: Due from GOCCs | B40: 137 | E40: =#REF! -> #REF!
A41: Due from LGUs | B41: 138 | E41: =#REF! -> #REF!
A42: Due from Other Funds | B42: 144 | E42: 626192.34
A43: Receivables-Disallowances/Charges | B43: 146 | E43: 23333.02
A44: Advances to Officers and Employees | B44: 148 | E44: 4540207.9
A45: Other Receivables | B45: 149 | E45: =#REF! -> #REF!
A46: Total Receivables | E46: =SUM(E38:E45) -> #REF!
A48: Inventories
A49: Office Supplies Inventory | B49: 155 | E49: 17842.5
...

Sheet Sched. fin'l. Position
A1: Republic of the Philippines
A2: Province of Leyte
A3: Municipality of Jaro
A5: SCHEDULE OF STATEMENT OF FINANCIAL POSITION
A6: As of MARCH 31,2022
A7: GENERAL FUND
A9: Account Code | E9: ACCOUNT TITLE | F9: AMOUNT
A11: 1 | B11: 01 | C11: CASH
A12: 1 | B12: 01 | C12: 01 | D12: Cash on Hand
A13: 1 | B13: 01 | C13: 01 | D13: 010 | E13: Cash Local Treasury
A14: 1 | B14: 01 | C14: 01 | D14: 020 | E14: Petty Cash
A15: 1 | B15: 01 | C15: 02 | D15: Cash in Bank - Local Currency
A16: 1 | B16: 01 | C16: 02 | D16: 010 | E16: Cash in Bank - Local Currency, Current Account | I16: =F13+F14+F16 -> 0
A17: 1 | B17: 01 | C17: 02 | D17: 020 | E17: Cash in Bank - Local Currency, Savings Account
A18: 1 | B18: 01 | C18: 03 | D18: Cash in Bank - Foreign Currency
A19: 1 | B19: 01 | C19: 03 | D19: 010 | E19: Cash in Bank - Foreign Currency, Current Account
A20: 1 | B20: 01 | C20: 03 | D20: 020 | E20: Cash in Bank - Foreign Currency, Savings Account
A21: TOTAL
A22: 1 | B22: 02 | C22: INVESTMENTS
A23: 1 | B23: 02 | C23: 01 | D23: Investments in Time Deposits
A24: 1 | B24: 02 | C24: 01 | D24: 010 | E24: Cash in Bank -Local Currency, Time Deposits
A25: 1 | B25: 02 | C25: 01 | D25: 020 | E25: Cash in Bank - Foreign Currency, Time Deposits
A26: 1 | B26: 02 | C26: 01 | D26: 030 | E26: Treasury Bills
A27: 1 | B27: 02 | C27: 02 | D27: Financial Assets at Fair Value Through Surplus or Deficit
A28: 1 | B28: 02 | C28: 02 | D28: 010 | E28: Financial Assets Held for Trading
A29: 1 | B29: 02 | C29: 02 | D29: 020 | E29: Financial Assets Designated at Fair Value Through Surplus or Deficit
A30: 1 | B30: 02 | C30: 03 | D30: Financial Assets - Held to Maturity
A31: 1 | B31: 02 | C31: 03 | D31: 010 | E31: Investments in Treasury Bills - Local
A32: 1 | B32: 02 | C32: 03 | D32: 011 | E32: Allowance for Impairment - Investments in Treasury Bills - Local
A33: 1 | B33: 02 | C33: 03 | D33: 020 | E33: Investments in Bonds-Local
A34: 1 | B34: 02 | C34: 03 | D34: 021 | E34: Allowance for Impairment - Investments in Bonds - Local
A35: 1 | B35: 02 | C35: 04 | D35: Financial Assets - Available for Sale
A36: 1 | B36: 02 | C36: 04 | D36: 010 | E36: Investments in Stocks
A37: 1 | B37: 02 | C37: 04 | D37: 020 | E37: Investments in Bonds
A38: 1 | B38: 02 | C38: 05 | D38: Financial Assets - Others
A39: 1 | B39: 02 | C39: 05 | D39: 010 | E39: Deposits on Letters of Credit
A40: 1 | B40: 02 | C40: 05 | D40: 011 | E40: Allowance for Impairment - Deposits in Letters of Credit
A41: 1 | B41: 02 | C41: 05 | D41: 020 | E41: Guaranty Deposits
A42: 1 | B42: 02 | C42: 05 | D42: 021 | E42: Allowance for Impairment - Guaranty Deposits
A43: 1 | B43: 02 | C43: 05 | D43: 990 | E43: Other Investments
...

Sheet Detailed Fin'L Position 
A1: MUNICIPALITY OF JARO
A2: Statement of Financial Position
A3: As of March 31,2022
A7: ASSETS
B8: CURRENT ASSETS
C9: CASH AND CASH EQUIVALENTS
D10: Cash on Hand
E11: Cash Local Treasury | O11: ='Sched. fin''l. Position'!F13 -> 0
E12: Petty Cash
D13: Cash in Banks - Local Currency
E14: Cash in Bank - Local Currency , Current Account
E15: Cash in Bank - Local Currency, Savings Account | O15: ='Sched. fin''l. Position'!F17 -> 0 | S15: ='[2]2019'!$E$13 -> 20343197
D16: Cash in Banks - Foreign Currency
E17: Cash in Bank - Foreign Currency , Current Account
E18: Cash in Bank - Foreign Currency, Savings Account
D19: Investments in Time Deposits (90 days)
E20: Cash in Bank -Local Currency, Time Deposits
E21: Cash in Bank - Foreign Currency, Time Deposits
E22: Treasury Bills
D23: Total Cash and Cash Equivalents
C24: INVESTMENTS
D25: Investments in Time Deposits (91 days to 1 year)
E26: Cash in Bank -Local Currency, Time Deposits
E27: Cash in Bank - Foreign Currency, Time Deposits
E28: Treasury Bills
D29: Financial Assets at Fair Value Through Surplus or Deficit
E30: Financial Assets Held for Trading
E31: Financial Assets Designated at Fair Value Through Surplus or Deficit
D32: Financial Assets - Held to Maturity
E33: Investments in Treasury Bills - Local
E34: Allowance for Impairment - Investments in Treasury Bills - Local
E35: Investments in Bonds-Local
E36: Allowance for Impairment - Investments in Bonds - Local
D37: Financial Assets - Available for Sale
E38: Investments in Stocks
E39: Investments in Bonds
D40: Financial Assets - Others
E41: Deposits on Letters of Credit
E42: Allowance for Impairment - Deposits in Letters of Credit
E43: Guaranty Deposits
...

Sheet Stmt. of Fin'l. Position
A1: Republic of the Philippines | H1: =H45 -> #REF!
A2: Province of Leyte
A3: MUNICIPALITY OF JARO
A5: STATEMENT OF FINANCIAL POSITION
A6: As of December 31, 2020
A7: GENERAL FUND
A9: PARTICULARS | D9: 2019 | F9: 2020
A10: ASSETS
B11: CURRENT ASSETS
C12: Cash and Cash Equivalents | D12: ='Sched. fin''l. Position'!F21 -> 0 | F12: 1.3458281e+08
C13: Investments
C14: Receivables | F14: 42773139
C15: Inventories | D15: ='Sched. fin''l. Position'!F157 -> 0 | F15: 6523268.8
C16: Prepayment and Deferred Charges | F16: 855449.75
A17: TOTAL CURRENT ASSETS | D17: =SUM(D12:D16) -> 0 | F17: =SUM(F12:F16) -> 1.8473467e+08
B18: NON-CURRENT ASSETS
C19: Investments | F19: =[4]DECEMBER!$J$14 -> 72000
C20: Receivables | F20: 168842.18
C21: Investment Property | F21: 2175110
C22: Property, Plant & Equipment | F22: 2.3472037e+08
C23: Biological Assets
C24: Intangible Assets | F24: 328599
A26: TOTAL NON-CURRENT ASSETS | F26: =SUM(F19:F24) -> 2.3746492e+08
A27: T O T A L A S S E T S | D27: =D17+D26 -> 0 | F27: =SUM(F17+F26) -> 4.2219959e+08
A28: LIABILITIES
B29: CURRENT LIABILITIES
C30: Financial Liabilities | D30: =SUM('Sched. fin''l. Position'!F360) -> 0 | F30: 67694.71
C31: Inter-Agency Payables | D31: ='Sched. fin''l. Position'!F387 -> 0 | F31: 14264606
C32: Intra-Agency Payables | D32: =SUM('Sched. fin''l. Position'!F393) -> 0 | F32: 5734628.4
C33: Trust Liablilities | D33: =SUM('Sched. fin''l. Position'!F401) -> 0 | F33: 1608601.6
C34: Deferred Credits/Unearned Income | F34: -
A35: TOTAL CURRENT LIABILITIES | D35: =SUM(D30:D34) -> 0 | F35: =SUM(F30:F34) -> 21675531
B36: NON-CURRENT LIABILITIES
C37: Financial Liablilities | D37: =SUM('Sched. fin''l. Position'!F374) -> 0 | F37: 464169.2
C38: Deferred Credits/Unearned Income | D38: =SUM('Sched. fin''l. Position'!F410) -> 0 | F38: 16156053
C39: Provisions | D39: ='Sched. fin''l. Position'!F415 -> 0
C40: Other Payables | D40: =SUM('Sched. fin''l. Position'!F418) -> 0 | F40: 546567.84
A41: TOTAL NON-CURRENT LIABILITIES | D41: =SUM(D37:D40) -> 0 | F41: =SUM(F37:F40) -> 17166790
A42: T O T A L L I A B I L I T I E S | D42: =SUM(D35,D41) -> 0 | F42: =SUM(F35+F41) -> 38842321
A43: NET ASSETS/EQUITY
...

Sheet CASH FLOW
A1: Republic of the Philippines
A2: Province of Leyte
A3: Municipality of Jaro
A5: STATEMENT OF CONDENSED CASH FLOWS
A6: GENERAL FUND
A7: As of March 31,2022
A8: P A R T I C U L A R S | F8: 2019
A9: CASH FLOW FROM OPERATING ACTIVITIES
A10: Cash Inflows
B11: Collection from Taxpayers
B12: Share from Internal Revenue Allotment
B13: Receipts from Business/Service Income
B14: Interest Income
B15: Dividend Income
B16: Other Receipts
B17: Total Cash Inflows | I17: =SUM(I12:I16) -> 0
A18: Cash Outflows
B19: Payment of Expenses
B20: Payments to Suppliers and Creditors | K20: 22617691
B21: Payments to Employees | K21: 69810565
B22: Interest Expense
B23: Other Expenses | K23: 99345644
B24: Total Cash Outflows
A25: Net Cash Flows from Operating Activities
A26: CASH FLOW FROM INVESTING ACTIVITIES
A27: Cash Inflows
B28: Proceeds from Sale of Investment Property
B29: Proceeds from Sale/Disposal of Property, Plant and Equipment
B30: Proceeds from Sale of Non-Current Investments
B31: Collection of Principal on Loans to Other Entities
B32: Total Cash Inflows
A33: Cash Outflows
B34: Purchase/Construction of Investment Property
B35: Purchase/Construction of Property, Plant and Equipment | K35: 6081097.3
B36: Investment
B37: Purchase of Bearer Biological Assets
B38: Purchase of Intangible Assets
B39: Grant of Loans
B40: Total Cash Outflows
A41: Net Cash Flows from Investing Activities
...

Sheet Balance Sheet
A1: Republic of the Philippines
A2: Province o0f Leyte
A3: Municipality of Jaro
A5: BALANCE SHEET
A6: General Fund
A7: As of December 31, 2015
A8: (With Comparative Figures for CY 2014)
G11: 2015 | I11: 2014
A12: ASSETS
A13: CURRENT ASSETS
A14: CASH
A15: Cash on Hand
B16: Cash in Vault | G16: ='Schedule Balance Sheet'!E13 -> 3359712.5 | I16: 587123.05
B17: Cash-Disbursing Officers
B18: Petty Cash Fund | G18: ='Schedule Balance Sheet'!E17 -> 43642.37 | I18: 43642.37
B19: Payroll Fund | G19: ='Schedule Balance Sheet'!E19 -> #REF! | I19: 0.01
A20: Cash in Banks-Local Currency
B21: Cash in Bank-Local Currency, Current Account | G21: ='Schedule Balance Sheet'!E33 -> 71163818 | I21: 29001618
B22: Cash in Bank-Local Currency, Savings Account
B23: Cash in Bank-Local Currency, Time Deposits
A24: Cash in Banks-Foreign Currency
B25: Cash in Bank-Foreign Currency, Current Account
B26: Cash in Bank-Foreign Currency, Savings Account
B27: Cash in Bank-Foreign Currency, Time Deposits
A28: Total Cash | G28: =SUM(G15:G27) -> #REF! | I28: =SUM(I15:I27) -> 29632383
A29: RECEIVABLES
A30: Receivable Account
B31: Accounts Receivable
B32: Notes Receivables
B33: Due from Officers and Employees | G33: 0 | I33: 643610.24
B34: Loans Receivables-GOCCs
B35: Loans Receivables-Others
B36: Loans Receivables-LGUs
B37: Real Propery Tax Receivable | G37: ='Schedule Balance Sheet'!E38 -> 24158078 | I37: 24118803
B38: Special Education Tax Receivable
B39: Interests Receivable
A40: Inter-agency Receivables
B41: Due from NGAs | G41: ='Schedule Balance Sheet'!E39 -> #REF! | I41: 33742.13
B42: Due from GOCCs | G42: ='Schedule Balance Sheet'!E40 -> #REF! | I42: 3050.23
B43: Due from LGUs | G43: ='Schedule Balance Sheet'!E41 -> #REF! | I43: 85141.1
...

Sheet Subsidiary Schedule
A1: Republic of the Philippines
A2: Province of Leyte
A3: MUNICIPALITY OF JARO
A5: SUBSIDIARY SCHEDULE
A6: As of December 31, 2019
A7: G E N E R A L F U N D
A9: ACCOUNT CODE | D9: PARTICULARS | E9: AMOUNT | I9: 1 | J9: 1 | K9: 2 | L9: 3 | M9: 4 | N9: 5
A10: Schedule | B10: 1 - | C10: 1-01-01-010 | D10: Cash Local Treasury | E10: ='[5]Cash Local Treasury'!$H$440 -> 397449.11 | H10: DEBIT | I10: =SUM(E10,E14,E24,E26,E28,E30,E32,E34,E48,E50,E52,E128,E130,E132,E134,E136,E138,E140,E142,E144,E146,E148,E150,E152,E156,E158,E160,E162,E164,E166) -> 2.09604e+08 | J10: =SUM(E168,E170,E172,E174,E176,E178,E182,E184,E186,E188,E190,E192,E194,E196,E198,E200) -> 87798437 | L10: =E314 -> 16512.58 | M10: =E322 -> 87927.35 | N10: =SUM(E378:E500) -> 1.0410666e+08 | O10: =SUM(I10:N10) -> 4.0161354e+08
A11: Schedule | B11: 2 - | D11: Petty Cash | H11: CREDIT | I11: =SUM(E202,E204,E206,E208,E210,E212,E214,E216,E218,E220,E222,E226) -> 10835277 | K11: =SUM(E233,E235,E243,E258,E264,E269,E279,E287,E292,E301,E303,E305,E307) -> 38648355 | L11: =E312 -> 2.0633173e+08 | M11: =SUM(E316,E318,E320,E324,E326,E328,E330,E332,E334,E336,E338,E340,E342,E344,E346,E348,E350,E352,E354,E356,E358,E360,E362,E364,E366,E368,E370,E372,E374,E376) -> 1.381462e+08 | O11: =SUM(I11:N11) -> 3.9396156e+08
C12: 1-01-01-020 - 1 | D12: GENERAL FUND | E12: ='[5]Petty Cash-1'!$G$47 -> 21642.37 | H12: DIFFERENCE | N12: TB TOTAL | O12: =[6]December!$F$186 -> 3.6359049e+08
C13: 1-01-01-020 - 2 | D13: AICS | E13: ='[5]Petty Cash-2'!$G$46 -> 22000 | O13: =O12-O11 -> -30371071
C14: TOTAL | E14: =SUM(E12:E13) -> 43642.37
A16: Schedule | B16: 3 - | C16: 1-01-02-010 | D16: Cash in Bank - Local Currency, Current Account
C17: 1-01-02-010 - 1A | D17: IRA | E17: ='[5]CIB- Mun. IRA'!$H$1826 -> 49207976
C18: 1-01-02-010 - 1B | D18: RIMMP | E18: ='[5]CIB-RIMMP'!$G$45 -> 14328.66
C19: 1-01-02-010 - 1C | D19: LGU EQUITY - PNP | E19: ='[5]CIB- LGU Equity'!$G$45 -> 33326.04
C20: 1-01-02-010 - 2 | D20: LBP 20% | E20: ='[5]CIB-20% (-2)'!$G$72 -> 1005024.4
C21: 1-01-02-010 - 3 | D21: PPSB (5%) | E21: =SUM('[5]CIB-3-70%'!$H$88,'[5]CIB-3-30% QUICK RESPONSE FUND'!$G$46) -> 0
C22: 1-01-02-010 - 4 | D22: DBP (20%) | E22: ='[5]CIB (-4) - DBP (20%)'!$G$84 -> 15454977
C23: 1-01-02-010 - 5 | D23: DBP (5%) | E23: ='[5]CIB (-5) - DBP (5%)'!$G$75 -> 23209543
C24: TOTAL | E24: =SUM(E17:E23) -> 88925175
A26: Schedule | B26: 4 - | C26: 1-02-05-990 | D26: Other Investments | E26: ='[7]Other Investments'!$G$45 -> 72000
A28: Schedule | B28: 5 - | C28: 1-03-01-020 | D28: Real Property Tax Receivable | E28: ='[8]RPT Receivable'!$G$141 -> 17255192
A30: Schedule | B30: 6 - | C30: 1-03-03-010 | D30: Due from National Government Agencies | E30: ='[8]Due from Nat''l Gov''t Agencies'!$G$45 -> 33742.13
A32: Schedule | B32: 7 - | C32: 1-03-03-020 | D32: Due from GOCCs | E32: ='[8]Due from GOCCs'!$G$45 -> 45818.23
A34: Schedule | B34: 8 - | C34: 1-03-03-030 | D34: Due from LGUs | E34: ='[8]Due from LGUs'!$G$45 -> 85141.1
A36: Schedule | B36: 9 - | C36: 1-03-04-050 | D36: Due from Other Funds
C37: 1-03-04-050 - 1 | E37: ='[8]Due from Other Funds - Unknown'!$G$12 -> 616844.94
C38: 1-03-04-050 - 2 | D38: DBP | E38: ='[8]Due from Other Funds-DBP'!$G$48 -> 3204899.5
C39: 1-03-04-050 - 3 | D39: SEF | E39: ='[8]Due from Other Funds-SEF'!$G$68 -> 7394.72
C40: 1-03-04-050 - 4 | D40: TRUST FUND | E40: ='[8]Due from Other Funds-TF'!$G$73 -> -115307.86
C41: 1-03-04-050 - 5 | D41: SALINTUBIG | E41: ='[8]Due from Other Funds-SALINTUBIG'!$G$62 -> 9985053.5
C42: 1-03-04-050 - 6 | D42: PCF | E42: ='[8]Due from Other Funds-PCF'!$G$45 -> 127
C43: 1-03-04-050 - 7 | D43: GPBP | E43: ='[8]Due from Other Funds - GPBP'!$G$52 -> 0
C44: 1-03-04-050 - 8 | D44: JARO SPORTS COMPLEX (JSC) | E44: ='[8]Due from Other Funds - JSC'!$G$50 -> 4164799.1
C45: 1-03-04-050 - 9 | D45: KFW | E45: ='[8]Due from Other Funds - KWF'!$G$55 -> 3166644.7
C46: 1-03-04-050 - 10 | D46: RAY 2 | E46: ='[8]Due from Other Funds - RAY 2'!$G$45 -> 0
C47: 1-03-04-050 - 11 | D47: RAY 3 | E47: ='[8]Due from Other Funds - RAY 3'!$G$46 -> 5625
C48: TOTAL | E48: =SUM(E37:E47) -> 21036081
A50: Schedule | B50: 10 - | C50: 1-03-05-010 | D50: Advances for Operating Expenses | E50: =[9]December!$C$20 -> 709400
...
